{
 "cells": [
  {
   "cell_type": "code",
   "execution_count": 1,
   "id": "16b2da0b",
   "metadata": {},
   "outputs": [
    {
     "name": "stdout",
     "output_type": "stream",
     "text": [
      "Defaulting to user installation because normal site-packages is not writeable\n",
      "\u001b[33mWARNING: Ignoring invalid distribution -eft (/home2/palash/.local/lib/python3.10/site-packages)\u001b[0m\u001b[33m\n",
      "\u001b[0m\u001b[33mWARNING: Ignoring invalid distribution -ransformers (/home2/palash/.local/lib/python3.10/site-packages)\u001b[0m\u001b[33m\n",
      "\u001b[0m\n",
      "\u001b[1m[\u001b[0m\u001b[34;49mnotice\u001b[0m\u001b[1;39;49m]\u001b[0m\u001b[39;49m A new release of pip is available: \u001b[0m\u001b[31;49m25.1\u001b[0m\u001b[39;49m -> \u001b[0m\u001b[32;49m25.1.1\u001b[0m\n",
      "\u001b[1m[\u001b[0m\u001b[34;49mnotice\u001b[0m\u001b[1;39;49m]\u001b[0m\u001b[39;49m To update, run: \u001b[0m\u001b[32;49mpip install --upgrade pip\u001b[0m\n",
      "\u001b[31mERROR: Could not open requirements file: [Errno 2] No such file or directory: 'pytorch'\u001b[0m\u001b[31m\n",
      "\u001b[0mDefaulting to user installation because normal site-packages is not writeable\n",
      "\u001b[33mWARNING: Ignoring invalid distribution -eft (/home2/palash/.local/lib/python3.10/site-packages)\u001b[0m\u001b[33m\n",
      "\u001b[0m\u001b[33mWARNING: Ignoring invalid distribution -ransformers (/home2/palash/.local/lib/python3.10/site-packages)\u001b[0m\u001b[33m\n",
      "\u001b[0m\u001b[33mWARNING: Ignoring invalid distribution -eft (/home2/palash/.local/lib/python3.10/site-packages)\u001b[0m\u001b[33m\n",
      "\u001b[0m\u001b[33mWARNING: Ignoring invalid distribution -ransformers (/home2/palash/.local/lib/python3.10/site-packages)\u001b[0m\u001b[33m\n",
      "\u001b[0mRequirement already satisfied: torch==2.5.1 in /home2/palash/.local/lib/python3.10/site-packages (2.5.1)\n",
      "Requirement already satisfied: filelock in /home2/palash/.local/lib/python3.10/site-packages (from torch==2.5.1) (3.14.0)\n",
      "Requirement already satisfied: typing-extensions>=4.8.0 in /home2/palash/.local/lib/python3.10/site-packages (from torch==2.5.1) (4.12.2)\n",
      "Requirement already satisfied: networkx in /home2/palash/.local/lib/python3.10/site-packages (from torch==2.5.1) (3.1)\n",
      "Requirement already satisfied: jinja2 in /usr/local/lib/python3.10/dist-packages (from torch==2.5.1) (3.1.2)\n",
      "Requirement already satisfied: fsspec in /home2/palash/.local/lib/python3.10/site-packages (from torch==2.5.1) (2023.10.0)\n",
      "Requirement already satisfied: nvidia-cuda-nvrtc-cu12==12.4.127 in /home2/palash/.local/lib/python3.10/site-packages (from torch==2.5.1) (12.4.127)\n",
      "Requirement already satisfied: nvidia-cuda-runtime-cu12==12.4.127 in /home2/palash/.local/lib/python3.10/site-packages (from torch==2.5.1) (12.4.127)\n",
      "Requirement already satisfied: nvidia-cuda-cupti-cu12==12.4.127 in /home2/palash/.local/lib/python3.10/site-packages (from torch==2.5.1) (12.4.127)\n",
      "Requirement already satisfied: nvidia-cudnn-cu12==9.1.0.70 in /home2/palash/.local/lib/python3.10/site-packages (from torch==2.5.1) (9.1.0.70)\n",
      "Requirement already satisfied: nvidia-cublas-cu12==12.4.5.8 in /home2/palash/.local/lib/python3.10/site-packages (from torch==2.5.1) (12.4.5.8)\n",
      "Requirement already satisfied: nvidia-cufft-cu12==11.2.1.3 in /home2/palash/.local/lib/python3.10/site-packages (from torch==2.5.1) (11.2.1.3)\n",
      "Requirement already satisfied: nvidia-curand-cu12==10.3.5.147 in /home2/palash/.local/lib/python3.10/site-packages (from torch==2.5.1) (10.3.5.147)\n",
      "Requirement already satisfied: nvidia-cusolver-cu12==11.6.1.9 in /home2/palash/.local/lib/python3.10/site-packages (from torch==2.5.1) (11.6.1.9)\n",
      "Requirement already satisfied: nvidia-cusparse-cu12==12.3.1.170 in /home2/palash/.local/lib/python3.10/site-packages (from torch==2.5.1) (12.3.1.170)\n",
      "Requirement already satisfied: nvidia-nccl-cu12==2.21.5 in /home2/palash/.local/lib/python3.10/site-packages (from torch==2.5.1) (2.21.5)\n",
      "Requirement already satisfied: nvidia-nvtx-cu12==12.4.127 in /home2/palash/.local/lib/python3.10/site-packages (from torch==2.5.1) (12.4.127)\n",
      "Requirement already satisfied: nvidia-nvjitlink-cu12==12.4.127 in /home2/palash/.local/lib/python3.10/site-packages (from torch==2.5.1) (12.4.127)\n",
      "Requirement already satisfied: triton==3.1.0 in /home2/palash/.local/lib/python3.10/site-packages (from torch==2.5.1) (3.1.0)\n",
      "Requirement already satisfied: sympy==1.13.1 in /home2/palash/.local/lib/python3.10/site-packages (from torch==2.5.1) (1.13.1)\n",
      "Requirement already satisfied: mpmath<1.4,>=1.1.0 in /home2/palash/.local/lib/python3.10/site-packages (from sympy==1.13.1->torch==2.5.1) (1.3.0)\n",
      "Requirement already satisfied: MarkupSafe>=2.0 in /home2/palash/.local/lib/python3.10/site-packages (from jinja2->torch==2.5.1) (2.1.2)\n",
      "\u001b[33mWARNING: Ignoring invalid distribution -eft (/home2/palash/.local/lib/python3.10/site-packages)\u001b[0m\u001b[33m\n",
      "\u001b[0m\u001b[33mWARNING: Ignoring invalid distribution -ransformers (/home2/palash/.local/lib/python3.10/site-packages)\u001b[0m\u001b[33m\n",
      "\u001b[0m\u001b[33mWARNING: Error parsing dependencies of distro-info: Invalid version: '1.1build1'\u001b[0m\u001b[33m\n",
      "\u001b[0m\u001b[33mWARNING: Error parsing dependencies of gpg: Invalid version: '1.16.0-unknown'\u001b[0m\u001b[33m\n",
      "\u001b[0m\u001b[33mWARNING: Error parsing dependencies of python-debian: Invalid version: '0.1.43ubuntu1'\u001b[0m\u001b[33m\n",
      "\u001b[0m\u001b[33mWARNING: Ignoring invalid distribution -eft (/home2/palash/.local/lib/python3.10/site-packages)\u001b[0m\u001b[33m\n",
      "\u001b[0m\u001b[33mWARNING: Ignoring invalid distribution -ransformers (/home2/palash/.local/lib/python3.10/site-packages)\u001b[0m\u001b[33m\n",
      "\u001b[0m\n",
      "\u001b[1m[\u001b[0m\u001b[34;49mnotice\u001b[0m\u001b[1;39;49m]\u001b[0m\u001b[39;49m A new release of pip is available: \u001b[0m\u001b[31;49m25.1\u001b[0m\u001b[39;49m -> \u001b[0m\u001b[32;49m25.1.1\u001b[0m\n",
      "\u001b[1m[\u001b[0m\u001b[34;49mnotice\u001b[0m\u001b[1;39;49m]\u001b[0m\u001b[39;49m To update, run: \u001b[0m\u001b[32;49mpip install --upgrade pip\u001b[0m\n",
      "Defaulting to user installation because normal site-packages is not writeable\n",
      "\u001b[33mWARNING: Ignoring invalid distribution -eft (/home2/palash/.local/lib/python3.10/site-packages)\u001b[0m\u001b[33m\n",
      "\u001b[0m\u001b[33mWARNING: Ignoring invalid distribution -ransformers (/home2/palash/.local/lib/python3.10/site-packages)\u001b[0m\u001b[33m\n",
      "\u001b[0m\u001b[33mWARNING: Ignoring invalid distribution -eft (/home2/palash/.local/lib/python3.10/site-packages)\u001b[0m\u001b[33m\n",
      "\u001b[0m\u001b[33mWARNING: Ignoring invalid distribution -ransformers (/home2/palash/.local/lib/python3.10/site-packages)\u001b[0m\u001b[33m\n",
      "\u001b[0m\u001b[31mERROR: Could not find a version that satisfies the requirement bitsandbytes==0.3.0 (from versions: 0.31.8, 0.32.0, 0.32.1, 0.32.2, 0.32.3, 0.33.0, 0.33.1, 0.34.0, 0.35.0, 0.35.1, 0.35.2, 0.35.3, 0.35.4, 0.36.0, 0.36.0.post1, 0.36.0.post2, 0.37.0, 0.37.1, 0.37.2, 0.38.0, 0.38.0.post1, 0.38.0.post2, 0.38.1, 0.39.0, 0.39.1, 0.40.0, 0.40.0.post1, 0.40.0.post2, 0.40.0.post3, 0.40.0.post4, 0.40.1, 0.40.1.post1, 0.40.2, 0.41.0, 0.41.1, 0.41.2, 0.41.2.post1, 0.41.2.post2, 0.41.3, 0.41.3.post1, 0.41.3.post2, 0.42.0, 0.43.0, 0.43.1, 0.43.2, 0.43.3, 0.44.0rc1, 0.44.0, 0.44.1, 0.45.0, 0.45.1, 0.45.2, 0.45.3, 0.45.4, 0.45.5, 0.46.0)\u001b[0m\u001b[31m\n",
      "\u001b[0m\n",
      "\u001b[1m[\u001b[0m\u001b[34;49mnotice\u001b[0m\u001b[1;39;49m]\u001b[0m\u001b[39;49m A new release of pip is available: \u001b[0m\u001b[31;49m25.1\u001b[0m\u001b[39;49m -> \u001b[0m\u001b[32;49m25.1.1\u001b[0m\n",
      "\u001b[1m[\u001b[0m\u001b[34;49mnotice\u001b[0m\u001b[1;39;49m]\u001b[0m\u001b[39;49m To update, run: \u001b[0m\u001b[32;49mpip install --upgrade pip\u001b[0m\n",
      "\u001b[31mERROR: No matching distribution found for bitsandbytes==0.3.0\u001b[0m\u001b[31m\n",
      "\u001b[0mDefaulting to user installation because normal site-packages is not writeable\n",
      "\u001b[33mWARNING: Ignoring invalid distribution -eft (/home2/palash/.local/lib/python3.10/site-packages)\u001b[0m\u001b[33m\n",
      "\u001b[0m\u001b[33mWARNING: Ignoring invalid distribution -ransformers (/home2/palash/.local/lib/python3.10/site-packages)\u001b[0m\u001b[33m\n",
      "\u001b[0m\u001b[33mWARNING: Ignoring invalid distribution -eft (/home2/palash/.local/lib/python3.10/site-packages)\u001b[0m\u001b[33m\n",
      "\u001b[0m\u001b[33mWARNING: Ignoring invalid distribution -ransformers (/home2/palash/.local/lib/python3.10/site-packages)\u001b[0m\u001b[33m\n",
      "\u001b[0mRequirement already satisfied: transformers==4.49.0 in /home2/palash/.local/lib/python3.10/site-packages (4.49.0)\n",
      "Requirement already satisfied: filelock in /home2/palash/.local/lib/python3.10/site-packages (from transformers==4.49.0) (3.14.0)\n",
      "Requirement already satisfied: huggingface-hub<1.0,>=0.26.0 in /home2/palash/.local/lib/python3.10/site-packages (from transformers==4.49.0) (0.30.2)\n",
      "Requirement already satisfied: numpy>=1.17 in /home2/palash/.local/lib/python3.10/site-packages (from transformers==4.49.0) (1.26.1)\n",
      "Requirement already satisfied: packaging>=20.0 in /home2/palash/.local/lib/python3.10/site-packages (from transformers==4.49.0) (23.2)\n",
      "Requirement already satisfied: pyyaml>=5.1 in /home2/palash/.local/lib/python3.10/site-packages (from transformers==4.49.0) (6.0)\n",
      "Requirement already satisfied: regex!=2019.12.17 in /home2/palash/.local/lib/python3.10/site-packages (from transformers==4.49.0) (2022.10.31)\n",
      "Requirement already satisfied: requests in /home2/palash/.local/lib/python3.10/site-packages (from transformers==4.49.0) (2.32.3)\n",
      "Requirement already satisfied: tokenizers<0.22,>=0.21 in /home2/palash/.local/lib/python3.10/site-packages (from transformers==4.49.0) (0.21.1)\n",
      "Requirement already satisfied: safetensors>=0.4.1 in /home2/palash/.local/lib/python3.10/site-packages (from transformers==4.49.0) (0.4.5)\n",
      "Requirement already satisfied: tqdm>=4.27 in /home2/palash/.local/lib/python3.10/site-packages (from transformers==4.49.0) (4.67.0)\n",
      "Requirement already satisfied: fsspec>=2023.5.0 in /home2/palash/.local/lib/python3.10/site-packages (from huggingface-hub<1.0,>=0.26.0->transformers==4.49.0) (2023.10.0)\n",
      "Requirement already satisfied: typing-extensions>=3.7.4.3 in /home2/palash/.local/lib/python3.10/site-packages (from huggingface-hub<1.0,>=0.26.0->transformers==4.49.0) (4.12.2)\n",
      "Requirement already satisfied: charset-normalizer<4,>=2 in /usr/local/lib/python3.10/dist-packages (from requests->transformers==4.49.0) (3.0.1)\n",
      "Requirement already satisfied: idna<4,>=2.5 in /usr/lib/python3/dist-packages (from requests->transformers==4.49.0) (3.3)\n",
      "Requirement already satisfied: urllib3<3,>=1.21.1 in /home2/palash/.local/lib/python3.10/site-packages (from requests->transformers==4.49.0) (1.26.15)\n",
      "Requirement already satisfied: certifi>=2017.4.17 in /usr/lib/python3/dist-packages (from requests->transformers==4.49.0) (2020.6.20)\n",
      "\u001b[33mWARNING: Ignoring invalid distribution -eft (/home2/palash/.local/lib/python3.10/site-packages)\u001b[0m\u001b[33m\n",
      "\u001b[0m\u001b[33mWARNING: Ignoring invalid distribution -ransformers (/home2/palash/.local/lib/python3.10/site-packages)\u001b[0m\u001b[33m\n",
      "\u001b[0m\u001b[33mWARNING: Error parsing dependencies of distro-info: Invalid version: '1.1build1'\u001b[0m\u001b[33m\n",
      "\u001b[0m\u001b[33mWARNING: Error parsing dependencies of gpg: Invalid version: '1.16.0-unknown'\u001b[0m\u001b[33m\n",
      "\u001b[0m\u001b[33mWARNING: Error parsing dependencies of python-debian: Invalid version: '0.1.43ubuntu1'\u001b[0m\u001b[33m\n",
      "\u001b[0m\u001b[33mWARNING: Ignoring invalid distribution -eft (/home2/palash/.local/lib/python3.10/site-packages)\u001b[0m\u001b[33m\n",
      "\u001b[0m\u001b[33mWARNING: Ignoring invalid distribution -ransformers (/home2/palash/.local/lib/python3.10/site-packages)\u001b[0m\u001b[33m\n",
      "\u001b[0m\n",
      "\u001b[1m[\u001b[0m\u001b[34;49mnotice\u001b[0m\u001b[1;39;49m]\u001b[0m\u001b[39;49m A new release of pip is available: \u001b[0m\u001b[31;49m25.1\u001b[0m\u001b[39;49m -> \u001b[0m\u001b[32;49m25.1.1\u001b[0m\n",
      "\u001b[1m[\u001b[0m\u001b[34;49mnotice\u001b[0m\u001b[1;39;49m]\u001b[0m\u001b[39;49m To update, run: \u001b[0m\u001b[32;49mpip install --upgrade pip\u001b[0m\n",
      "/home2/palash/.local/lib/python3.10/site-packages/torchvision/io/image.py:13: UserWarning: Failed to load image Python extension: '/home2/palash/.local/lib/python3.10/site-packages/torchvision/image.so: undefined symbol: _ZN3c1017RegisterOperatorsD1Ev'If you don't plan on using image functionality from `torchvision.io`, you can ignore this warning. Otherwise, there might be something wrong with your environment. Did you have `libjpeg` or `libpng` installed before building `torchvision` from source?\n",
      "  warn(\n",
      "/home2/palash/.local/lib/python3.10/site-packages/timm/models/hub.py:4: FutureWarning: Importing from timm.models.hub is deprecated, please import via timm.models\n",
      "  warnings.warn(f\"Importing from {__name__} is deprecated, please import via timm.models\", FutureWarning)\n",
      "2025-06-23 13:14:37.853873: I tensorflow/core/util/port.cc:153] oneDNN custom operations are on. You may see slightly different numerical results due to floating-point round-off errors from different computation orders. To turn them off, set the environment variable `TF_ENABLE_ONEDNN_OPTS=0`.\n",
      "2025-06-23 13:14:37.874089: E external/local_xla/xla/stream_executor/cuda/cuda_fft.cc:477] Unable to register cuFFT factory: Attempting to register factory for plugin cuFFT when one has already been registered\n",
      "WARNING: All log messages before absl::InitializeLog() is called are written to STDERR\n",
      "E0000 00:00:1750664677.895669 3562857 cuda_dnn.cc:8310] Unable to register cuDNN factory: Attempting to register factory for plugin cuDNN when one has already been registered\n",
      "E0000 00:00:1750664677.902259 3562857 cuda_blas.cc:1418] Unable to register cuBLAS factory: Attempting to register factory for plugin cuBLAS when one has already been registered\n",
      "2025-06-23 13:14:37.926530: I tensorflow/core/platform/cpu_feature_guard.cc:210] This TensorFlow binary is optimized to use available CPU instructions in performance-critical operations.\n",
      "To enable the following instructions: AVX2 AVX512F AVX512_VNNI FMA, in other operations, rebuild TensorFlow with the appropriate compiler flags.\n",
      "False\n",
      "\n",
      "===================================BUG REPORT===================================\n",
      "/home2/palash/.local/lib/python3.10/site-packages/bitsandbytes/cuda_setup/main.py:166: UserWarning: Welcome to bitsandbytes. For bug reports, please run\n",
      "\n",
      "python -m bitsandbytes\n",
      "\n",
      "\n",
      "  warn(msg)\n",
      "================================================================================\n",
      "The following directories listed in your path were found to be non-existent: {PosixPath('/home2/palash/.local/lib/python3.10/site-packages/cv2/../../lib64')}\n",
      "/home2/palash/.local/lib/python3.10/site-packages/bitsandbytes/cuda_setup/main.py:166: UserWarning: /home2/palash/.local/lib/python3.10/site-packages/cv2/../../lib64:/usr/local/cuda-12.5/lib64:/usr/local/cuda-12.5/lib64:/usr/local/cuda-12.5/lib64:/usr/local/cuda-12.5/lib64: did not contain ['libcudart.so', 'libcudart.so.11.0', 'libcudart.so.12.0'] as expected! Searching further paths...\n",
      "  warn(msg)\n",
      "The following directories listed in your path were found to be non-existent: {PosixPath('vs/workbench/api/node/extensionHostProcess')}\n",
      "The following directories listed in your path were found to be non-existent: {PosixPath('http'), PosixPath('//xen03.iitd.ac.in'), PosixPath('3128')}\n",
      "The following directories listed in your path were found to be non-existent: {PosixPath('http'), PosixPath('//xen03.iitd.ac.in'), PosixPath('3128')}\n",
      "The following directories listed in your path were found to be non-existent: {PosixPath('//matplotlib_inline.backend_inline'), PosixPath('module')}\n",
      "The following directories listed in your path were found to be non-existent: {PosixPath('{}}'), PosixPath('\"en\",\"osLocale\"'), PosixPath('{\"userLocale\"'), PosixPath('\"en\",\"availableLanguages\"'), PosixPath('\"en\",\"resolvedLanguage\"'), PosixPath('\"en\",\"defaultMessagesFile\"'), PosixPath('\"/home2/palash/.vscode-server/cli/servers/Stable-258e40fedc6cb8edf399a463ce3a9d32e7e1f6f3/server/out/nls.messages.json\",\"locale\"')}\n",
      "CUDA_SETUP: WARNING! libcudart.so not found in any environmental path. Searching in backup paths...\n",
      "DEBUG: Possible options found for libcudart.so: {PosixPath('/usr/local/cuda/lib64/libcudart.so')}\n",
      "CUDA SETUP: PyTorch settings found: CUDA_VERSION=124, Highest Compute Capability: 8.0.\n",
      "CUDA SETUP: To manually override the PyTorch CUDA version please see:https://github.com/TimDettmers/bitsandbytes/blob/main/how_to_use_nonpytorch_cuda.md\n",
      "CUDA SETUP: Required library version not found: libbitsandbytes_cuda124.so. Maybe you need to compile it from source?\n",
      "CUDA SETUP: Defaulting to libbitsandbytes_cpu.so...\n",
      "\n",
      "================================================ERROR=====================================\n",
      "CUDA SETUP: CUDA detection failed! Possible reasons:\n",
      "1. You need to manually override the PyTorch CUDA version. Please see: \"https://github.com/TimDettmers/bitsandbytes/blob/main/how_to_use_nonpytorch_cuda.md\n",
      "2. CUDA driver not installed\n",
      "3. CUDA not installed\n",
      "4. You have multiple conflicting CUDA libraries\n",
      "5. Required library not pre-compiled for this bitsandbytes release!\n",
      "CUDA SETUP: If you compiled from source, try again with `make CUDA_VERSION=DETECTED_CUDA_VERSION` for example, `make CUDA_VERSION=113`.\n",
      "CUDA SETUP: The CUDA version for the compile might depend on your conda install. Inspect CUDA version via `conda list | grep cuda`.\n",
      "================================================================================\n",
      "\n",
      "CUDA SETUP: Something unexpected happened. Please compile from source:\n",
      "git clone https://github.com/TimDettmers/bitsandbytes.git\n",
      "cd bitsandbytes\n",
      "CUDA_VERSION=124\n",
      "python setup.py install\n",
      "CUDA SETUP: Setup Failed!\n",
      "Traceback (most recent call last):\n",
      "  File \"/home2/palash/p1_Jailbreak/MiniGPT4/visualization_miniGPT4.py\", line 16, in <module>\n",
      "    from minigpt4.conversation.conversation import Chat\n",
      "  File \"/home2/palash/p1_Jailbreak/MiniGPT4/minigpt4/__init__.py\", line 16, in <module>\n",
      "    from minigpt4.models import *\n",
      "  File \"/home2/palash/p1_Jailbreak/MiniGPT4/minigpt4/models/__init__.py\", line 13, in <module>\n",
      "    from minigpt4.models.base_model import BaseModel\n",
      "  File \"/home2/palash/p1_Jailbreak/MiniGPT4/minigpt4/models/base_model.py\", line 17, in <module>\n",
      "    from peft import (\n",
      "  File \"/home2/palash/.local/lib/python3.10/site-packages/peft/__init__.py\", line 22, in <module>\n",
      "    from .auto import (\n",
      "  File \"/home2/palash/.local/lib/python3.10/site-packages/peft/auto.py\", line 30, in <module>\n",
      "    from .mapping import MODEL_TYPE_TO_PEFT_MODEL_MAPPING\n",
      "  File \"/home2/palash/.local/lib/python3.10/site-packages/peft/mapping.py\", line 20, in <module>\n",
      "    from .peft_model import (\n",
      "  File \"/home2/palash/.local/lib/python3.10/site-packages/peft/peft_model.py\", line 39, in <module>\n",
      "    from .tuners import (\n",
      "  File \"/home2/palash/.local/lib/python3.10/site-packages/peft/tuners/__init__.py\", line 21, in <module>\n",
      "    from .lora import LoraConfig, LoraModel\n",
      "  File \"/home2/palash/.local/lib/python3.10/site-packages/peft/tuners/lora.py\", line 42, in <module>\n",
      "    import bitsandbytes as bnb\n",
      "  File \"/home2/palash/.local/lib/python3.10/site-packages/bitsandbytes/__init__.py\", line 6, in <module>\n",
      "    from . import cuda_setup, utils, research\n",
      "  File \"/home2/palash/.local/lib/python3.10/site-packages/bitsandbytes/research/__init__.py\", line 1, in <module>\n",
      "    from . import nn\n",
      "  File \"/home2/palash/.local/lib/python3.10/site-packages/bitsandbytes/research/nn/__init__.py\", line 1, in <module>\n",
      "    from .modules import LinearFP8Mixed, LinearFP8Global\n",
      "  File \"/home2/palash/.local/lib/python3.10/site-packages/bitsandbytes/research/nn/modules.py\", line 8, in <module>\n",
      "    from bitsandbytes.optim import GlobalOptimManager\n",
      "  File \"/home2/palash/.local/lib/python3.10/site-packages/bitsandbytes/optim/__init__.py\", line 6, in <module>\n",
      "    from bitsandbytes.cextension import COMPILED_WITH_CUDA\n",
      "  File \"/home2/palash/.local/lib/python3.10/site-packages/bitsandbytes/cextension.py\", line 20, in <module>\n",
      "    raise RuntimeError('''\n",
      "RuntimeError: \n",
      "        CUDA Setup failed despite GPU being available. Please run the following command to get more information:\n",
      "\n",
      "        python -m bitsandbytes\n",
      "\n",
      "        Inspect the output of the command and see if you can locate CUDA libraries. You might need to add them\n",
      "        to your LD_LIBRARY_PATH. If you suspect a bug, please take the information from python -m bitsandbytes\n",
      "        and open an issue at: https://github.com/TimDettmers/bitsandbytes/issues\n"
     ]
    }
   ],
   "source": [
    "import os\n",
    "os.environ[\"CUDA_VISIBLE_DEVICES\"] = \"2\"\n",
    "\n",
    "! pip install conda install pytorch torchvision torchaudio pytorch-cuda=11.8 -c pytorch -c nvidia\n",
    "! pip install torch==2.5.1\n",
    "! pip install bitsandbytes==0.3.0\n",
    "! pip install transformers==4.49.0\n",
    "! python3 visualization_miniGPT4.py --cfg-path '/home2/palash/p1_Jailbreak/MiniGPT4/eval_configs/minigpt4_eval.yaml'"
   ]
  },
  {
   "cell_type": "code",
   "execution_count": 10,
   "id": "f01936ea",
   "metadata": {},
   "outputs": [
    {
     "name": "stdout",
     "output_type": "stream",
     "text": [
      "2.7.1+cu126\n"
     ]
    }
   ],
   "source": [
    "import torch\n",
    "print(torch.__version__)"
   ]
  },
  {
   "cell_type": "code",
   "execution_count": 6,
   "id": "36d34bed",
   "metadata": {},
   "outputs": [
    {
     "name": "stderr",
     "output_type": "stream",
     "text": [
      "usage: ipykernel_launcher.py [-h] --cfg-path CFG_PATH [--name NAME]\n",
      "                             [--ckpt CKPT] [--eval_opt EVAL_OPT]\n",
      "                             [--max_new_tokens MAX_NEW_TOKENS]\n",
      "                             [--batch_size BATCH_SIZE] [--lora_r LORA_R]\n",
      "                             [--lora_alpha LORA_ALPHA]\n",
      "                             [--options OPTIONS [OPTIONS ...]]\n",
      "ipykernel_launcher.py: error: the following arguments are required: --cfg-path\n"
     ]
    },
    {
     "ename": "SystemExit",
     "evalue": "2",
     "output_type": "error",
     "traceback": [
      "An exception has occurred, use %tb to see the full traceback.\n",
      "\u001b[0;31mSystemExit\u001b[0m\u001b[0;31m:\u001b[0m 2\n"
     ]
    },
    {
     "name": "stderr",
     "output_type": "stream",
     "text": [
      "/usr/local/lib/python3.10/dist-packages/IPython/core/interactiveshell.py:3450: UserWarning: To exit: use 'exit', 'quit', or Ctrl-D.\n",
      "  warn(\"To exit: use 'exit', 'quit', or Ctrl-D.\", stacklevel=1)\n"
     ]
    }
   ],
   "source": [
    "def list_of_str(arg):\n",
    "    return list(map(str, arg.split(',')))\n",
    "\n",
    "parser = eval_parser()\n",
    "# parser.add_argument(\"--cfg-path\", type=list_of_str, default='/home2/palash/p1_Jailbreak/MiniGPT4/eval_configs/minigpt4_eval.yaml', help=\"dataset to evaluate\")\n",
    "args = parser.parse_args()\n",
    "cfg = Config(args)\n",
    "cfg['cfg-path'] = f'/home2/palash/p1_Jailbreak/MiniGPT4/eval_configs/minigpt4_eval.yaml'\n",
    "\n",
    "print(cfg)\n",
    "\n",
    "model, vis_processor = init_model(args)\n",
    "model.eval()\n",
    "model = model.cuda().half()  # <-- Convert model to float16 (half precision)\n",
    "\n",
    "print(f'*********************************')\n",
    "\n",
    "\n",
    "image_path = './metaphor_0.png'  # replace with your image\n",
    "question = \"What the pile of cigerattes signify here in this context?\"\n",
    "image = Image.open(image_path).convert('RGB')\n",
    "image_tensor = vis_processor(image).unsqueeze(0).cuda().half()  # <-- Convert image to float16\n",
    "prompt = f\"###Human: <Img><ImageHere></Img> {question} ###Assistant:\"\n",
    "texts = [prompt]\n",
    "\n",
    "with torch.no_grad():\n",
    "    output = model.generate(image_tensor, texts, max_new_tokens=50)\n",
    "\n",
    "print(f'I/P prompt: {prompt}')\n",
    "print(\"Answer:\", output[0])\n"
   ]
  }
 ],
 "metadata": {
  "kernelspec": {
   "display_name": "jb_miniGPT4",
   "language": "python",
   "name": "jb_minigpt4"
  },
  "language_info": {
   "codemirror_mode": {
    "name": "ipython",
    "version": 3
   },
   "file_extension": ".py",
   "mimetype": "text/x-python",
   "name": "python",
   "nbconvert_exporter": "python",
   "pygments_lexer": "ipython3",
   "version": "3.10.6"
  }
 },
 "nbformat": 4,
 "nbformat_minor": 5
}
